Errors:
Exception in Tkinter callback
Traceback (most recent call last):
  File "/Library/Frameworks/Python.framework/Versions/3.12/lib/python3.12/tkinter/__init__.py", line 1968, in __call__
    return self.func(*args)
           ^^^^^^^^^^^^^^^^
  File "/Users/matthewyang/NotepadEE/Notepad==.py", line 131, in clear
    write_cache()
  File "/Users/matthewyang/NotepadEE/Notepad==.py", line 72, in write_cache
    with open(current_file, 'w') as file:
         ^^^^^^^^^^^^^^^^^^^^^^^
FileNotFoundError: [Errno 2] No such file or directory: ''
Exception in Tkinter callback
Traceback (most recent call last):
  File "/Library/Frameworks/Python.framework/Versions/3.12/lib/python3.12/tkinter/__init__.py", line 1968, in __call__
    return self.func(*args)
           ^^^^^^^^^^^^^^^^
  File "/Library/Frameworks/Python.framework/Versions/3.12/lib/python3.12/tkinter/__init__.py", line 862, in callit
    func(*args)
  File "/Users/matthewyang/NotepadEE/Notepad==.py", line 72, in write_cache
    with open(current_file, 'w') as file:
         ^^^^^^^^^^^^^^^^^^^^^^^
FileNotFoundError: [Errno 2] No such file or directory: ''
Exception in Tkinter callback
Traceback (most recent call last):
  File "/Library/Frameworks/Python.framework/Versions/3.12/lib/python3.12/tkinter/__init__.py", line 1968, in __call__
    return self.func(*args)
           ^^^^^^^^^^^^^^^^
  File "/Library/Frameworks/Python.framework/Versions/3.12/lib/python3.12/tkinter/__init__.py", line 862, in callit
    func(*args)
  File "/Users/matthewyang/NotepadEE/Notepad==.py", line 72, in write_cache
    with open(current_file, 'w') as file:
         ^^^^^^^^^^^^^^^^^^^^^^^
FileNotFoundError: [Errno 2] No such file or directory: ''